2022-02-15 18:01:02,720:app:WARNING:user:1 tutorials - read action failed with errors: 
2022-02-15 18:02:20,744:app:WARNING:user:1 tutorials - read action failed with errors: 
2022-02-15 18:02:41,425:app:WARNING:user:1 tutorials - read action failed with errors: Œ¯Ë·Í‡
2022-02-16 16:52:31,210:videoblog:ERROR:Exception on /profile [GET]
Traceback (most recent call last):
  File "C:\Users\Max\AppData\Local\Programs\Python\Python38\lib\site-packages\flask\app.py", line 2073, in wsgi_app
    response = self.full_dispatch_request()
  File "C:\Users\Max\AppData\Local\Programs\Python\Python38\lib\site-packages\flask\app.py", line 1518, in full_dispatch_request
    rv = self.handle_user_exception(e)
  File "C:\Users\Max\AppData\Local\Programs\Python\Python38\lib\site-packages\flask\app.py", line 1516, in full_dispatch_request
    rv = self.dispatch_request()
  File "C:\Users\Max\AppData\Local\Programs\Python\Python38\lib\site-packages\flask\app.py", line 1502, in dispatch_request
    return self.ensure_sync(self.view_functions[rule.endpoint])(**req.view_args)
  File "C:\Users\Max\AppData\Local\Programs\Python\Python38\lib\site-packages\flask\views.py", line 84, in view
    return current_app.ensure_sync(self.dispatch_request)(*args, **kwargs)
  File "C:\Users\Max\AppData\Local\Programs\Python\Python38\lib\site-packages\flask\views.py", line 158, in dispatch_request
    return current_app.ensure_sync(meth)(*args, **kwargs)
  File "C:\Users\Max\AppData\Local\Programs\Python\Python38\lib\site-packages\flask_apispec\annotations.py", line 122, in wrapped
    return wrapper(*args, **kwargs)
  File "C:\Users\Max\AppData\Local\Programs\Python\Python38\lib\site-packages\flask_apispec\wrapper.py", line 33, in __call__
    mv = self.marshal_result(rv, status_code)
  File "C:\Users\Max\AppData\Local\Programs\Python\Python38\lib\site-packages\flask_apispec\wrapper.py", line 67, in marshal_result
    return format_response(output)  # type: Response
  File "C:\Users\Max\AppData\Local\Programs\Python\Python38\lib\site-packages\flask\json\__init__.py", line 355, in jsonify
    f"{dumps(data, indent=indent, separators=separators)}\n",
  File "C:\Users\Max\AppData\Local\Programs\Python\Python38\lib\site-packages\flask\json\__init__.py", line 133, in dumps
    rv = _json.dumps(obj, **kwargs)
  File "C:\Users\Max\AppData\Local\Programs\Python\Python38\lib\json\__init__.py", line 234, in dumps
    return cls(
  File "C:\Users\Max\AppData\Local\Programs\Python\Python38\lib\json\encoder.py", line 199, in encode
    chunks = self.iterencode(o, _one_shot=True)
  File "C:\Users\Max\AppData\Local\Programs\Python\Python38\lib\json\encoder.py", line 257, in iterencode
    return _iterencode(o, 0)
  File "C:\Users\Max\AppData\Local\Programs\Python\Python38\lib\site-packages\flask\json\__init__.py", line 57, in default
    return super().default(o)
  File "C:\Users\Max\AppData\Local\Programs\Python\Python38\lib\json\encoder.py", line 179, in default
    raise TypeError(f'Object of type {o.__class__.__name__} '
TypeError: Object of type function is not JSON serializable
2022-02-16 16:53:48,970:videoblog:ERROR:Exception on /profile [GET]
Traceback (most recent call last):
  File "C:\Users\Max\AppData\Local\Programs\Python\Python38\lib\site-packages\flask\app.py", line 2073, in wsgi_app
    response = self.full_dispatch_request()
  File "C:\Users\Max\AppData\Local\Programs\Python\Python38\lib\site-packages\flask\app.py", line 1518, in full_dispatch_request
    rv = self.handle_user_exception(e)
  File "C:\Users\Max\AppData\Local\Programs\Python\Python38\lib\site-packages\flask\app.py", line 1516, in full_dispatch_request
    rv = self.dispatch_request()
  File "C:\Users\Max\AppData\Local\Programs\Python\Python38\lib\site-packages\flask\app.py", line 1502, in dispatch_request
    return self.ensure_sync(self.view_functions[rule.endpoint])(**req.view_args)
  File "C:\Users\Max\AppData\Local\Programs\Python\Python38\lib\site-packages\flask\views.py", line 84, in view
    return current_app.ensure_sync(self.dispatch_request)(*args, **kwargs)
  File "C:\Users\Max\AppData\Local\Programs\Python\Python38\lib\site-packages\flask\views.py", line 158, in dispatch_request
    return current_app.ensure_sync(meth)(*args, **kwargs)
  File "C:\Users\Max\AppData\Local\Programs\Python\Python38\lib\site-packages\flask_apispec\annotations.py", line 122, in wrapped
    return wrapper(*args, **kwargs)
  File "C:\Users\Max\AppData\Local\Programs\Python\Python38\lib\site-packages\flask_apispec\wrapper.py", line 33, in __call__
    mv = self.marshal_result(rv, status_code)
  File "C:\Users\Max\AppData\Local\Programs\Python\Python38\lib\site-packages\flask_apispec\wrapper.py", line 67, in marshal_result
    return format_response(output)  # type: Response
  File "C:\Users\Max\AppData\Local\Programs\Python\Python38\lib\site-packages\flask\json\__init__.py", line 355, in jsonify
    f"{dumps(data, indent=indent, separators=separators)}\n",
  File "C:\Users\Max\AppData\Local\Programs\Python\Python38\lib\site-packages\flask\json\__init__.py", line 133, in dumps
    rv = _json.dumps(obj, **kwargs)
  File "C:\Users\Max\AppData\Local\Programs\Python\Python38\lib\json\__init__.py", line 234, in dumps
    return cls(
  File "C:\Users\Max\AppData\Local\Programs\Python\Python38\lib\json\encoder.py", line 199, in encode
    chunks = self.iterencode(o, _one_shot=True)
  File "C:\Users\Max\AppData\Local\Programs\Python\Python38\lib\json\encoder.py", line 257, in iterencode
    return _iterencode(o, 0)
  File "C:\Users\Max\AppData\Local\Programs\Python\Python38\lib\site-packages\flask\json\__init__.py", line 57, in default
    return super().default(o)
  File "C:\Users\Max\AppData\Local\Programs\Python\Python38\lib\json\encoder.py", line 179, in default
    raise TypeError(f'Object of type {o.__class__.__name__} '
TypeError: Object of type function is not JSON serializable
2022-02-16 16:54:11,018:videoblog:ERROR:Exception on /profile [GET]
Traceback (most recent call last):
  File "C:\Users\Max\AppData\Local\Programs\Python\Python38\lib\site-packages\flask\app.py", line 2073, in wsgi_app
    response = self.full_dispatch_request()
  File "C:\Users\Max\AppData\Local\Programs\Python\Python38\lib\site-packages\flask\app.py", line 1518, in full_dispatch_request
    rv = self.handle_user_exception(e)
  File "C:\Users\Max\AppData\Local\Programs\Python\Python38\lib\site-packages\flask\app.py", line 1516, in full_dispatch_request
    rv = self.dispatch_request()
  File "C:\Users\Max\AppData\Local\Programs\Python\Python38\lib\site-packages\flask\app.py", line 1502, in dispatch_request
    return self.ensure_sync(self.view_functions[rule.endpoint])(**req.view_args)
  File "C:\Users\Max\AppData\Local\Programs\Python\Python38\lib\site-packages\flask\views.py", line 84, in view
    return current_app.ensure_sync(self.dispatch_request)(*args, **kwargs)
  File "C:\Users\Max\AppData\Local\Programs\Python\Python38\lib\site-packages\flask\views.py", line 158, in dispatch_request
    return current_app.ensure_sync(meth)(*args, **kwargs)
  File "C:\Users\Max\AppData\Local\Programs\Python\Python38\lib\site-packages\flask_apispec\annotations.py", line 122, in wrapped
    return wrapper(*args, **kwargs)
  File "C:\Users\Max\AppData\Local\Programs\Python\Python38\lib\site-packages\flask_apispec\wrapper.py", line 33, in __call__
    mv = self.marshal_result(rv, status_code)
  File "C:\Users\Max\AppData\Local\Programs\Python\Python38\lib\site-packages\flask_apispec\wrapper.py", line 67, in marshal_result
    return format_response(output)  # type: Response
  File "C:\Users\Max\AppData\Local\Programs\Python\Python38\lib\site-packages\flask\json\__init__.py", line 355, in jsonify
    f"{dumps(data, indent=indent, separators=separators)}\n",
  File "C:\Users\Max\AppData\Local\Programs\Python\Python38\lib\site-packages\flask\json\__init__.py", line 133, in dumps
    rv = _json.dumps(obj, **kwargs)
  File "C:\Users\Max\AppData\Local\Programs\Python\Python38\lib\json\__init__.py", line 234, in dumps
    return cls(
  File "C:\Users\Max\AppData\Local\Programs\Python\Python38\lib\json\encoder.py", line 199, in encode
    chunks = self.iterencode(o, _one_shot=True)
  File "C:\Users\Max\AppData\Local\Programs\Python\Python38\lib\json\encoder.py", line 257, in iterencode
    return _iterencode(o, 0)
  File "C:\Users\Max\AppData\Local\Programs\Python\Python38\lib\site-packages\flask\json\__init__.py", line 57, in default
    return super().default(o)
  File "C:\Users\Max\AppData\Local\Programs\Python\Python38\lib\json\encoder.py", line 179, in default
    raise TypeError(f'Object of type {o.__class__.__name__} '
TypeError: Object of type function is not JSON serializable
2022-02-16 16:57:25,394:videoblog:ERROR:Exception on /profile [GET]
Traceback (most recent call last):
  File "C:\Users\Max\AppData\Local\Programs\Python\Python38\lib\site-packages\flask\app.py", line 2073, in wsgi_app
    response = self.full_dispatch_request()
  File "C:\Users\Max\AppData\Local\Programs\Python\Python38\lib\site-packages\flask\app.py", line 1518, in full_dispatch_request
    rv = self.handle_user_exception(e)
  File "C:\Users\Max\AppData\Local\Programs\Python\Python38\lib\site-packages\flask\app.py", line 1516, in full_dispatch_request
    rv = self.dispatch_request()
  File "C:\Users\Max\AppData\Local\Programs\Python\Python38\lib\site-packages\flask\app.py", line 1502, in dispatch_request
    return self.ensure_sync(self.view_functions[rule.endpoint])(**req.view_args)
  File "C:\Users\Max\AppData\Local\Programs\Python\Python38\lib\site-packages\flask\views.py", line 84, in view
    return current_app.ensure_sync(self.dispatch_request)(*args, **kwargs)
  File "C:\Users\Max\AppData\Local\Programs\Python\Python38\lib\site-packages\flask\views.py", line 158, in dispatch_request
    return current_app.ensure_sync(meth)(*args, **kwargs)
  File "C:\Users\Max\AppData\Local\Programs\Python\Python38\lib\site-packages\flask_apispec\annotations.py", line 122, in wrapped
    return wrapper(*args, **kwargs)
  File "C:\Users\Max\AppData\Local\Programs\Python\Python38\lib\site-packages\flask_apispec\wrapper.py", line 33, in __call__
    mv = self.marshal_result(rv, status_code)
  File "C:\Users\Max\AppData\Local\Programs\Python\Python38\lib\site-packages\flask_apispec\wrapper.py", line 67, in marshal_result
    return format_response(output)  # type: Response
  File "C:\Users\Max\AppData\Local\Programs\Python\Python38\lib\site-packages\flask\json\__init__.py", line 355, in jsonify
    f"{dumps(data, indent=indent, separators=separators)}\n",
  File "C:\Users\Max\AppData\Local\Programs\Python\Python38\lib\site-packages\flask\json\__init__.py", line 133, in dumps
    rv = _json.dumps(obj, **kwargs)
  File "C:\Users\Max\AppData\Local\Programs\Python\Python38\lib\json\__init__.py", line 234, in dumps
    return cls(
  File "C:\Users\Max\AppData\Local\Programs\Python\Python38\lib\json\encoder.py", line 199, in encode
    chunks = self.iterencode(o, _one_shot=True)
  File "C:\Users\Max\AppData\Local\Programs\Python\Python38\lib\json\encoder.py", line 257, in iterencode
    return _iterencode(o, 0)
  File "C:\Users\Max\AppData\Local\Programs\Python\Python38\lib\site-packages\flask\json\__init__.py", line 57, in default
    return super().default(o)
  File "C:\Users\Max\AppData\Local\Programs\Python\Python38\lib\json\encoder.py", line 179, in default
    raise TypeError(f'Object of type {o.__class__.__name__} '
TypeError: Object of type function is not JSON serializable
2022-02-16 16:59:00,443:videoblog:ERROR:Exception on /profile [GET]
Traceback (most recent call last):
  File "C:\Users\Max\AppData\Local\Programs\Python\Python38\lib\site-packages\flask\app.py", line 2073, in wsgi_app
    response = self.full_dispatch_request()
  File "C:\Users\Max\AppData\Local\Programs\Python\Python38\lib\site-packages\flask\app.py", line 1518, in full_dispatch_request
    rv = self.handle_user_exception(e)
  File "C:\Users\Max\AppData\Local\Programs\Python\Python38\lib\site-packages\flask\app.py", line 1516, in full_dispatch_request
    rv = self.dispatch_request()
  File "C:\Users\Max\AppData\Local\Programs\Python\Python38\lib\site-packages\flask\app.py", line 1502, in dispatch_request
    return self.ensure_sync(self.view_functions[rule.endpoint])(**req.view_args)
  File "C:\Users\Max\AppData\Local\Programs\Python\Python38\lib\site-packages\flask\views.py", line 84, in view
    return current_app.ensure_sync(self.dispatch_request)(*args, **kwargs)
  File "C:\Users\Max\AppData\Local\Programs\Python\Python38\lib\site-packages\flask\views.py", line 158, in dispatch_request
    return current_app.ensure_sync(meth)(*args, **kwargs)
  File "C:\Users\Max\AppData\Local\Programs\Python\Python38\lib\site-packages\flask_jwt_extended\view_decorators.py", line 127, in decorator
    return current_app.ensure_sync(fn)(*args, **kwargs)
  File "C:\Users\Max\AppData\Local\Programs\Python\Python38\lib\site-packages\flask_apispec\annotations.py", line 122, in wrapped
    return wrapper(*args, **kwargs)
  File "C:\Users\Max\AppData\Local\Programs\Python\Python38\lib\site-packages\flask_apispec\wrapper.py", line 29, in __call__
    response = self.call_view(*args, **kwargs)
  File "C:\Users\Max\AppData\Local\Programs\Python\Python38\lib\site-packages\flask_apispec\wrapper.py", line 52, in call_view
    return self.func(*args, **kwargs)
TypeError: get() takes 0 positional arguments but 1 was given
2022-02-16 16:59:37,234:videoblog:ERROR:Exception on /profile [GET]
Traceback (most recent call last):
  File "C:\Users\Max\AppData\Local\Programs\Python\Python38\lib\site-packages\flask\app.py", line 2073, in wsgi_app
    response = self.full_dispatch_request()
  File "C:\Users\Max\AppData\Local\Programs\Python\Python38\lib\site-packages\flask\app.py", line 1518, in full_dispatch_request
    rv = self.handle_user_exception(e)
  File "C:\Users\Max\AppData\Local\Programs\Python\Python38\lib\site-packages\flask\app.py", line 1516, in full_dispatch_request
    rv = self.dispatch_request()
  File "C:\Users\Max\AppData\Local\Programs\Python\Python38\lib\site-packages\flask\app.py", line 1502, in dispatch_request
    return self.ensure_sync(self.view_functions[rule.endpoint])(**req.view_args)
  File "C:\Users\Max\AppData\Local\Programs\Python\Python38\lib\site-packages\flask_apispec\annotations.py", line 122, in wrapped
    return wrapper(*args, **kwargs)
  File "C:\Users\Max\AppData\Local\Programs\Python\Python38\lib\site-packages\flask_apispec\wrapper.py", line 29, in __call__
    response = self.call_view(*args, **kwargs)
  File "C:\Users\Max\AppData\Local\Programs\Python\Python38\lib\site-packages\flask_apispec\wrapper.py", line 52, in call_view
    return self.func(*args, **kwargs)
  File "C:\Users\Max\AppData\Local\Programs\Python\Python38\lib\site-packages\flask_jwt_extended\view_decorators.py", line 127, in decorator
    return current_app.ensure_sync(fn)(*args, **kwargs)
  File "C:\Users\Max\AppData\Local\Programs\Python\Python38\lib\site-packages\flask\views.py", line 84, in view
    return current_app.ensure_sync(self.dispatch_request)(*args, **kwargs)
  File "C:\Users\Max\AppData\Local\Programs\Python\Python38\lib\site-packages\flask\views.py", line 158, in dispatch_request
    return current_app.ensure_sync(meth)(*args, **kwargs)
  File "C:\Users\Max\AppData\Local\Programs\Python\Python38\lib\site-packages\flask_apispec\annotations.py", line 122, in wrapped
    return wrapper(*args, **kwargs)
  File "C:\Users\Max\AppData\Local\Programs\Python\Python38\lib\site-packages\flask_apispec\wrapper.py", line 29, in __call__
    response = self.call_view(*args, **kwargs)
  File "C:\Users\Max\AppData\Local\Programs\Python\Python38\lib\site-packages\flask_apispec\wrapper.py", line 52, in call_view
    return self.func(*args, **kwargs)
TypeError: get() takes 0 positional arguments but 1 was given
2022-02-16 17:01:13,859:videoblog:ERROR:Exception on /profile [GET]
Traceback (most recent call last):
  File "C:\Users\Max\AppData\Local\Programs\Python\Python38\lib\site-packages\flask\app.py", line 2073, in wsgi_app
    response = self.full_dispatch_request()
  File "C:\Users\Max\AppData\Local\Programs\Python\Python38\lib\site-packages\flask\app.py", line 1518, in full_dispatch_request
    rv = self.handle_user_exception(e)
  File "C:\Users\Max\AppData\Local\Programs\Python\Python38\lib\site-packages\flask\app.py", line 1516, in full_dispatch_request
    rv = self.dispatch_request()
  File "C:\Users\Max\AppData\Local\Programs\Python\Python38\lib\site-packages\flask\app.py", line 1502, in dispatch_request
    return self.ensure_sync(self.view_functions[rule.endpoint])(**req.view_args)
  File "C:\Users\Max\AppData\Local\Programs\Python\Python38\lib\site-packages\flask_apispec\annotations.py", line 122, in wrapped
    return wrapper(*args, **kwargs)
  File "C:\Users\Max\AppData\Local\Programs\Python\Python38\lib\site-packages\flask_apispec\wrapper.py", line 29, in __call__
    response = self.call_view(*args, **kwargs)
  File "C:\Users\Max\AppData\Local\Programs\Python\Python38\lib\site-packages\flask_apispec\wrapper.py", line 52, in call_view
    return self.func(*args, **kwargs)
  File "C:\Users\Max\AppData\Local\Programs\Python\Python38\lib\site-packages\flask_jwt_extended\view_decorators.py", line 127, in decorator
    return current_app.ensure_sync(fn)(*args, **kwargs)
  File "C:\Users\Max\AppData\Local\Programs\Python\Python38\lib\site-packages\flask\views.py", line 84, in view
    return current_app.ensure_sync(self.dispatch_request)(*args, **kwargs)
  File "C:\Users\Max\AppData\Local\Programs\Python\Python38\lib\site-packages\flask\views.py", line 158, in dispatch_request
    return current_app.ensure_sync(meth)(*args, **kwargs)
  File "C:\Users\Max\AppData\Local\Programs\Python\Python38\lib\site-packages\flask_apispec\annotations.py", line 122, in wrapped
    return wrapper(*args, **kwargs)
  File "C:\Users\Max\AppData\Local\Programs\Python\Python38\lib\site-packages\flask_apispec\wrapper.py", line 29, in __call__
    response = self.call_view(*args, **kwargs)
  File "C:\Users\Max\AppData\Local\Programs\Python\Python38\lib\site-packages\flask_apispec\wrapper.py", line 52, in call_view
    return self.func(*args, **kwargs)
TypeError: get() takes 0 positional arguments but 1 was given
2022-02-16 17:02:03,579:videoblog:ERROR:Exception on /profile [GET]
Traceback (most recent call last):
  File "C:\Users\Max\AppData\Local\Programs\Python\Python38\lib\site-packages\flask\app.py", line 2073, in wsgi_app
    response = self.full_dispatch_request()
  File "C:\Users\Max\AppData\Local\Programs\Python\Python38\lib\site-packages\flask\app.py", line 1518, in full_dispatch_request
    rv = self.handle_user_exception(e)
  File "C:\Users\Max\AppData\Local\Programs\Python\Python38\lib\site-packages\flask\app.py", line 1516, in full_dispatch_request
    rv = self.dispatch_request()
  File "C:\Users\Max\AppData\Local\Programs\Python\Python38\lib\site-packages\flask\app.py", line 1502, in dispatch_request
    return self.ensure_sync(self.view_functions[rule.endpoint])(**req.view_args)
  File "C:\Users\Max\AppData\Local\Programs\Python\Python38\lib\site-packages\flask\views.py", line 84, in view
    return current_app.ensure_sync(self.dispatch_request)(*args, **kwargs)
  File "C:\Users\Max\AppData\Local\Programs\Python\Python38\lib\site-packages\flask\views.py", line 158, in dispatch_request
    return current_app.ensure_sync(meth)(*args, **kwargs)
  File "C:\Users\Max\AppData\Local\Programs\Python\Python38\lib\site-packages\flask_apispec\annotations.py", line 122, in wrapped
    return wrapper(*args, **kwargs)
  File "C:\Users\Max\AppData\Local\Programs\Python\Python38\lib\site-packages\flask_apispec\wrapper.py", line 33, in __call__
    mv = self.marshal_result(rv, status_code)
  File "C:\Users\Max\AppData\Local\Programs\Python\Python38\lib\site-packages\flask_apispec\wrapper.py", line 67, in marshal_result
    return format_response(output)  # type: Response
  File "C:\Users\Max\AppData\Local\Programs\Python\Python38\lib\site-packages\flask\json\__init__.py", line 355, in jsonify
    f"{dumps(data, indent=indent, separators=separators)}\n",
  File "C:\Users\Max\AppData\Local\Programs\Python\Python38\lib\site-packages\flask\json\__init__.py", line 133, in dumps
    rv = _json.dumps(obj, **kwargs)
  File "C:\Users\Max\AppData\Local\Programs\Python\Python38\lib\json\__init__.py", line 234, in dumps
    return cls(
  File "C:\Users\Max\AppData\Local\Programs\Python\Python38\lib\json\encoder.py", line 199, in encode
    chunks = self.iterencode(o, _one_shot=True)
  File "C:\Users\Max\AppData\Local\Programs\Python\Python38\lib\json\encoder.py", line 257, in iterencode
    return _iterencode(o, 0)
  File "C:\Users\Max\AppData\Local\Programs\Python\Python38\lib\site-packages\flask\json\__init__.py", line 57, in default
    return super().default(o)
  File "C:\Users\Max\AppData\Local\Programs\Python\Python38\lib\json\encoder.py", line 179, in default
    raise TypeError(f'Object of type {o.__class__.__name__} '
TypeError: Object of type function is not JSON serializable
